<?xml version="1.0" encoding="utf-8"?>
<!-- =================================================================================== -->
<!-- |    This document was autogenerated by xacro from ex6.xacro                      | -->
<!-- |    EDITING THIS FILE BY HAND IS NOT RECOMMENDED                                 | -->
<!-- =================================================================================== -->
<robot name="kuka_LBR">
  <link name="base_link">
    <visual>
      <geometry>
        <box size="0.1 1.1 0.1"/>
      </geometry>
      <origin rpy="0 0 0" xyz="0 0 0"/>
      <material name="yellow">
        <color rgba="1 1 0 1"/>
      </material>
    </visual>
    <collision>
      <geometry>
        <cylinder length="0.1" radius="0.05"/>
      </geometry>
      <origin rpy="0 0 0" xyz="0 0 0"/>
    </collision>
  </link>
  <joint name="J0" type="prismatic">
    <parent link="base_link"/>
    <child link="L0"/>
    <origin xyz="0 0 0.15"/>
    <axis xyz="0 1 0"/>
    <limit effort="200" lower="-0.5" upper="0.5" velocity="2"/>
    <dynamics damping="50" friction="1"/>
  </joint>
  <link name="L0">
    <visual>
      <geometry>
        <cylinder length="0.2" radius="0.05"/>
      </geometry>
      <origin rpy="0 0 0" xyz="0 0 0"/>
      <material name="red">
        <color rgba="0 0 1 1"/>
      </material>
    </visual>
    <collision>
      <geometry>
        <cylinder length="0.2" radius="0.05"/>
      </geometry>
      <origin rpy="0 0 0" xyz="0 0 0"/>
    </collision>
    <inertial>
      <mass value="1"/>
      <inertia ixx="1.0" ixy="0.0" ixz="0.0" iyy="1.0" iyz="0.0" izz="1.0"/>
    </inertial>
  </link>
  <joint name="J1" type="revolute">
    <parent link="L0"/>
    <child link="L1"/>
    <origin xyz="0 0 0.15"/>
    <axis xyz="0 0 1"/>
    <limit effort="176" lower="-2.97" upper="2.97" velocity="1.71"/>
    <dynamics damping="50" friction="1"/>
  </joint>
  <link name="L1">
    <visual>
      <geometry>
        <cylinder length="0.2" radius="0.05"/>
      </geometry>
      <origin rpy="0 0 0" xyz="0 0 0"/>
      <material name="red">
        <color rgba="0 0 1 1"/>
      </material>
    </visual>
    <collision>
      <geometry>
        <cylinder length="0.2" radius="0.05"/>
      </geometry>
      <origin rpy="0 0 0" xyz="0 0 0"/>
    </collision>
    <inertial>
      <mass value="1"/>
      <inertia ixx="1.0" ixy="0.0" ixz="0.0" iyy="1.0" iyz="0.0" izz="1.0"/>
    </inertial>
  </link>
  <joint name="J2" type="revolute">
    <parent link="L1"/>
    <child link="L2"/>
    <origin xyz="0 0.1 0.1"/>
    <axis xyz="0 1 0"/>
    <limit effort="176" lower="-2.09" upper="2.09" velocity="1.71"/>
    <dynamics damping="50" friction="1"/>
  </joint>
  <link name="L2">
    <visual>
      <geometry>
        <cylinder length="0.2" radius="0.05"/>
      </geometry>
      <origin rpy="0 0 0" xyz="0 0 0"/>
      <material name="red">
        <color rgba="0 0 1 1"/>
      </material>
    </visual>
    <collision>
      <geometry>
        <cylinder length="0.2" radius="0.05"/>
      </geometry>
      <origin rpy="0 0 0" xyz="0 0 0"/>
    </collision>
    <inertial>
      <mass value="1"/>
      <inertia ixx="1.0" ixy="0.0" ixz="0.0" iyy="1.0" iyz="0.0" izz="1.0"/>
    </inertial>
  </link>
  <joint name="J3" type="revolute">
    <parent link="L2"/>
    <child link="L3"/>
    <origin xyz="0 0 0.2"/>
    <axis xyz="0 0 1"/>
    <limit effort="110" lower="-2.97" upper="2.97" velocity="1.74"/>
    <dynamics damping="50" friction="1"/>
  </joint>
  <link name="L3">
    <visual>
      <geometry>
        <cylinder length="0.2" radius="0.05"/>
      </geometry>
      <origin rpy="0 0 0" xyz="0 0 0"/>
      <material name="red">
        <color rgba="0 0 1 1"/>
      </material>
    </visual>
    <collision>
      <geometry>
        <cylinder length="0.2" radius="0.05"/>
      </geometry>
      <origin rpy="0 0 0" xyz="0 0 0"/>
    </collision>
    <inertial>
      <mass value="1"/>
      <inertia ixx="1.0" ixy="0.0" ixz="0.0" iyy="1.0" iyz="0.0" izz="1.0"/>
    </inertial>
  </link>
  <joint name="J4" type="revolute">
    <parent link="L3"/>
    <child link="L4"/>
    <origin xyz="0 -0.1 0.1"/>
    <axis xyz="0 -1 0"/>
    <limit effort="110" lower="-2.09" upper="2.09" velocity="2.27"/>
    <dynamics damping="50" friction="1"/>
  </joint>
  <link name="L4">
    <visual>
      <geometry>
        <cylinder length="0.2" radius="0.05"/>
      </geometry>
      <origin rpy="0 0 0" xyz="0 0 0"/>
      <material name="red">
        <color rgba="0 0 1 1"/>
      </material>
    </visual>
    <collision>
      <geometry>
        <cylinder length="0.2" radius="0.05"/>
      </geometry>
      <origin rpy="0 0 0" xyz="0 0 0"/>
    </collision>
    <inertial>
      <mass value="1"/>
      <inertia ixx="1.0" ixy="0.0" ixz="0.0" iyy="1.0" iyz="0.0" izz="1.0"/>
    </inertial>
  </link>
  <joint name="J5" type="revolute">
    <parent link="L4"/>
    <child link="L5"/>
    <origin xyz="0 0 0.2"/>
    <axis xyz="0 0 1"/>
    <limit effort="110" lower="-2.97" upper="2.97" velocity="0.70"/>
    <dynamics damping="50" friction="1"/>
  </joint>
  <link name="L5">
    <visual>
      <geometry>
        <cylinder length="0.2" radius="0.05"/>
      </geometry>
      <origin rpy="0 0 0" xyz="0 0 0"/>
      <material name="red">
        <color rgba="0 0 1 1"/>
      </material>
    </visual>
    <collision>
      <geometry>
        <cylinder length="0.2" radius="0.05"/>
      </geometry>
      <origin rpy="0 0 0" xyz="0 0 0"/>
    </collision>
    <inertial>
      <mass value="1"/>
      <inertia ixx="1.0" ixy="0.0" ixz="0.0" iyy="1.0" iyz="0.0" izz="1.0"/>
    </inertial>
  </link>
  <joint name="J6" type="revolute">
    <parent link="L5"/>
    <child link="L6"/>
    <origin xyz="0 0.1 0.1"/>
    <axis xyz="0 1 0"/>
    <limit effort="40" lower="-2.09" upper="2.09" velocity="3.14"/>
    <dynamics damping="50" friction="1"/>
  </joint>
  <link name="L6">
    <visual>
      <geometry>
        <cylinder length="0.2" radius="0.05"/>
      </geometry>
      <origin rpy="0 0 0" xyz="0 0 0"/>
      <material name="red">
        <color rgba="0 0 1 1"/>
      </material>
    </visual>
    <collision>
      <geometry>
        <cylinder length="0.2" radius="0.05"/>
      </geometry>
      <origin rpy="0 0 0" xyz="0 0 0"/>
    </collision>
    <inertial>
      <mass value="1"/>
      <inertia ixx="1.0" ixy="0.0" ixz="0.0" iyy="1.0" iyz="0.0" izz="1.0"/>
    </inertial>
  </link>
  <joint name="J7" type="revolute">
    <parent link="L6"/>
    <child link="ee"/>
    <origin xyz="0 0 0.15"/>
    <axis xyz="0 0 1"/>
    <limit effort="40" lower="-1.31" upper="1.31" velocity="3.14"/>
    <dynamics damping="50" friction="1"/>
  </joint>
  <link name="ee">
    <visual>
      <geometry>
        <cylinder length="0.1" radius="0.05"/>
      </geometry>
      <origin rpy="0 0 0" xyz="0 0 0"/>
      <material name="yellow">
        <color rgba="1 1 0 1"/>
      </material>
    </visual>
    <collision>
      <geometry>
        <cylinder length="0.1" radius="0.05"/>
      </geometry>
      <origin rpy="0 0 0" xyz="0 0 0"/>
    </collision>
    <inertial>
      <mass value="0"/>
      <inertia ixx="1.0" ixy="0.0" ixz="0.0" iyy="1.0" iyz="0.0" izz="1.0"/>
    </inertial>
  </link>
</robot>

